Workbook

Sheet Graphs
A1: Direct Central Totals (ms): | I1: Direct Distributed Totals (ms): | Q1: Broker Central Totals (ms): | Y1: Broker Distributed Totals (ms):
A2: ='Direct Central'!B9 -> 4020 | B2: ='Direct Central'!D9 -> 3004 | C2: ='Direct Central'!F9 -> 1013 | I2: ='Direct Distributed'!B9 -> 6860 | J2: ='Direct Distributed'!D9 -> 5862 | K2: ='Direct Distributed'!F9 -> 4875 | Q2: ='Broker Central'!B9 -> 3979 | R2: ='Broker Central'!D9 -> 2991 | S2: ='Broker Central'!F9 -> 1997 | Y2: ='Broker Distributed'!B9 -> 6871 | Z2: ='Broker Distributed'!D9 -> 5866 | AA2: ='Broker Distributed'!F9 -> 4870
A3: Sub1 | B3: Sub2 | C3: Sub3 | I3: Sub1 | J3: Sub2 | K3: Sub3 | Q3: Sub1 | R3: Sub2 | S3: Sub3 | Y3: Sub1 | Z3: Sub2 | AA3: Sub3

Sheet Direct Central
A2: 2023-02-28 15:12:22,129 - PubAppln - INFO - Publisher app configured. | C2: 2023-02-28 15:12:23,117 - PubAppln - INFO - Publisher app configured. | E2: 2023-02-28 15:12:24,136 - PubAppln - INFO - Publisher app configured.
A3: 2023-02-28 15:12:22,129 - PubAppln - INFO - Registering app with discovery service. | C3: 2023-02-28 15:12:23,117 - PubAppln - INFO - Registering app with discovery service. | E3: 2023-02-28 15:12:24,136 - PubAppln - INFO - Registering app with discovery service.
A4: 2023-02-28 15:12:22,133 - PubAppln - INFO - Publisher app registered. | C4: 2023-02-28 15:12:23,121 - PubAppln - INFO - Publisher app registered. | E4: 2023-02-28 15:12:24,139 - PubAppln - INFO - Publisher app registered.
A5: 2023-02-28 15:12:22,133 - PubAppln - INFO - Waiting for all ready from discovery service. | C5: 2023-02-28 15:12:23,121 - PubAppln - INFO - Waiting for all ready from discovery service. | E5: 2023-02-28 15:12:24,139 - PubAppln - INFO - Waiting for all ready from discovery service.
A6: 2023-02-28 15:12:27,140 - PubAppln - INFO - All sub and pub apps registered and ready. | C6: 2023-02-28 15:12:28,128 - PubAppln - INFO - All sub and pub apps registered and ready. | E6: 2023-02-28 15:12:27,143 - PubAppln - INFO - All sub and pub apps registered and ready.
A7: 2023-02-28 15:12:28,141 - PubAppln - INFO - Disseminating info on our topics. | C7: 2023-02-28 15:12:29,129 - PubAppln - INFO - Disseminating info on our topics. | E7: 2023-02-28 15:12:28,144 - PubAppln - INFO - Disseminating info on our topics.
A8: 2023-02-28 15:12:28,141 - PubAppln - INFO - Dissemination finished. Exiting. | C8: 2023-02-28 15:12:29,130 - PubAppln - INFO - Dissemination finished. Exiting. | E8: 2023-02-28 15:12:28,144 - PubAppln - INFO - Dissemination finished. Exiting.
B9: =29130-25110 -> 4020 | D9: =29130-26126 -> 3004 | F9: =28144-27131 -> 1013
A10: 2023-02-28 15:12:25,110 - SubAppln - INFO - Subscriber app configured. | C10: 2023-02-28 15:12:26,126 - SubAppln - INFO - Subscriber app configured. | E10: 2023-02-28 15:12:27,131 - SubAppln - INFO - Subscriber app configured.
A11: 2023-02-28 15:12:25,110 - SubAppln - INFO - Registering app with discovery service. | C11: 2023-02-28 15:12:26,126 - SubAppln - INFO - Registering app with discovery service. | E11: 2023-02-28 15:12:27,131 - SubAppln - INFO - Registering app with discovery service.
A12: 2023-02-28 15:12:25,112 - SubAppln - INFO - Subscriber app registered. | C12: 2023-02-28 15:12:26,128 - SubAppln - INFO - Subscriber app registered. | E12: 2023-02-28 15:12:27,133 - SubAppln - INFO - Subscriber app registered.
A13: 2023-02-28 15:12:25,112 - SubAppln - INFO - Waiting for all ready from discovery service. | C13: 2023-02-28 15:12:26,128 - SubAppln - INFO - Waiting for all ready from discovery service. | E13: 2023-02-28 15:12:27,133 - SubAppln - INFO - Waiting for all ready from discovery service.
A14: 2023-02-28 15:12:28,117 - SubAppln - INFO - All sub and pub apps registered and ready. | C14: 2023-02-28 15:12:28,132 - SubAppln - INFO - All sub and pub apps registered and ready. | E14: 2023-02-28 15:12:27,134 - SubAppln - INFO - All sub and pub apps registered and ready.
A15: 2023-02-28 15:12:28,117 - SubAppln - INFO - Locating all publishers for our topics. | C15: 2023-02-28 15:12:28,132 - SubAppln - INFO - Locating all publishers for our topics. | E15: 2023-02-28 15:12:27,134 - SubAppln - INFO - Locating all publishers for our topics.
A16: 2023-02-28 15:12:28,117 - SubAppln - INFO - Subscribing to relevant publishers. | C16: 2023-02-28 15:12:28,132 - SubAppln - INFO - Subscribing to relevant publishers. | E16: 2023-02-28 15:12:27,135 - SubAppln - INFO - Subscribing to relevant publishers.
A17: 2023-02-28 15:12:28,118 - SubAppln - INFO - Subscribed to publisher: tcp://10.0.0.2:5566 | C17: 2023-02-28 15:12:28,132 - SubAppln - INFO - Subscribed to publisher: tcp://10.0.0.2:5566 | E17: 2023-02-28 15:12:27,135 - SubAppln - INFO - Subscribed to publisher: tcp://10.0.0.2:5566
A18: 2023-02-28 15:12:28,118 - SubAppln - INFO - Subscribed to publisher: tcp://10.0.0.3:5566 | C18: 2023-02-28 15:12:28,132 - SubAppln - INFO - Subscribed to publisher: tcp://10.0.0.3:5566 | E18: 2023-02-28 15:12:27,135 - SubAppln - INFO - Subscribed to publisher: tcp://10.0.0.4:5566
A19: 2023-02-28 15:12:28,118 - SubAppln - INFO - Subscribed to publisher: tcp://10.0.0.4:5566 | C19: 2023-02-28 15:12:28,132 - SubAppln - INFO - Subscribed to publisher: tcp://10.0.0.4:5566 | E19: 2023-02-28 15:12:28,142 - SubAppln - INFO - Message from publisher: humidity:15.041918618405305
A20: 2023-02-28 15:12:28,142 - SubAppln - INFO - Message from publisher: location:Asia | C20: 2023-02-28 15:12:28,142 - SubAppln - INFO - Message from publisher: location:Asia | E20: 2023-02-28 15:12:28,142 - SubAppln - INFO - Message from publisher: humidity:91.65551790595926
A21: 2023-02-28 15:12:28,142 - SubAppln - INFO - Message from publisher: airquality:good | C21: 2023-02-28 15:12:28,142 - SubAppln - INFO - Message from publisher: pressure:996 | E21: 2023-02-28 15:12:28,142 - SubAppln - INFO - Message from publisher: humidity:91.60762905566419
... A28: 2023-02-28 15:12:28,142 - SubAppln - INFO - Message from publisher: weather:icy | C28: 2023-02-28 15:12:28,142 - SubAppln - INFO - Message from publisher: weather:rainy | E28: 2023-02-28 15:12:28,144 - SubAppln - INFO - Message from publisher: humidity:55.14343169886022
A29: 2023-02-28 15:12:28,142 - SubAppln - INFO - Message from publisher: humidity:91.65551790595926 | C29: 2023-02-28 15:12:28,142 - SubAppln - INFO - Message from publisher: location:Asia
A30: 2023-02-28 15:12:28,142 - SubAppln - INFO - Message from publisher: location:Africa | C30: 2023-02-28 15:12:28,142 - SubAppln - INFO - Message from publisher: pressure:1065
A31: 2023-02-28 15:12:28,142 - SubAppln - INFO - Message from publisher: airquality:poor | C31: 2023-02-28 15:12:28,142 - SubAppln - INFO - Message from publisher: weather:foggy
A32: 2023-02-28 15:12:28,142 - SubAppln - INFO - Message from publisher: pressure:871 | C32: 2023-02-28 15:12:28,142 - SubAppln - INFO - Message from publisher: location:Australia
A33: 2023-02-28 15:12:28,142 - SubAppln - INFO - Message from publisher: weather:rainy | C33: 2023-02-28 15:12:28,142 - SubAppln - INFO - Message from publisher: pressure:974
A34: 2023-02-28 15:12:28,142 - SubAppln - INFO - Message from publisher: humidity:91.60762905566419 | C34: 2023-02-28 15:12:28,142 - SubAppln - INFO - Message from publisher: weather:sunny
A35: 2023-02-28 15:12:28,142 - SubAppln - INFO - Message from publisher: location:Asia | C35: 2023-02-28 15:12:28,144 - SubAppln - INFO - Message from publisher: pressure:1017
A36: 2023-02-28 15:12:28,142 - SubAppln - INFO - Message from publisher: airquality:smog | C36: 2023-02-28 15:12:28,145 - SubAppln - INFO - Message from publisher: weather:foggy
A37: 2023-02-28 15:12:28,142 - SubAppln - INFO - Message from publisher: pressure:1065 | C37: 2023-02-28 15:12:28,145 - SubAppln - INFO - Message from publisher: pressure:970
A38: 2023-02-28 15:12:28,142 - SubAppln - INFO - Message from publisher: weather:foggy | C38: 2023-02-28 15:12:28,145 - SubAppln - INFO - Message from publisher: weather:sunny
A39: 2023-02-28 15:12:28,142 - SubAppln - INFO - Message from publisher: humidity:48.03981782580423 | C39: 2023-02-28 15:12:28,145 - SubAppln - INFO - Message from publisher: pressure:886
A40: 2023-02-28 15:12:28,142 - SubAppln - INFO - Message from publisher: location:Australia | C40: 2023-02-28 15:12:28,145 - SubAppln - INFO - Message from publisher: weather:sunny
... A49: 2023-02-28 15:12:28,145 - SubAppln - INFO - Message from publisher: weather:foggy | C49: 2023-02-28 15:12:29,130 - SubAppln - INFO - Message from publisher: pressure:877
A50: 2023-02-28 15:12:28,145 - SubAppln - INFO - Message from publisher: sound:73
A51: 2023-02-28 15:12:28,145 - SubAppln - INFO - Message from publisher: airquality:poor
A52: 2023-02-28 15:12:28,145 - SubAppln - INFO - Message from publisher: pressure:970
A53: 2023-02-28 15:12:28,145 - SubAppln - INFO - Message from publisher: humidity:74.13051755649298
A54: 2023-02-28 15:12:28,145 - SubAppln - INFO - Message from publisher: weather:sunny
A55: 2023-02-28 15:12:28,145 - SubAppln - INFO - Message from publisher: sound:79
...

Sheet Direct Distributed
A2: 2023-02-28 17:48:24,858 - PubAppln - INFO - Publisher app configured. | C2: 2023-02-28 17:48:25,854 - PubAppln - INFO - Publisher app configured. | E2: 2023-02-28 17:48:26,854 - PubAppln - INFO - Publisher app configured.
A3: 2023-02-28 17:48:24,858 - PubAppln - INFO - Registering app with discovery service. | C3: 2023-02-28 17:48:25,854 - PubAppln - INFO - Registering app with discovery service. | E3: 2023-02-28 17:48:26,854 - PubAppln - INFO - Registering app with discovery service.
A4: 2023-02-28 17:48:24,874 - PubAppln - INFO - Publisher app registered. | C4: 2023-02-28 17:48:25,876 - PubAppln - INFO - Publisher app registered. | E4: 2023-02-28 17:48:26,868 - PubAppln - INFO - Publisher app registered.
A5: 2023-02-28 17:48:24,874 - PubAppln - INFO - Waiting for all ready from discovery service. | C5: 2023-02-28 17:48:25,876 - PubAppln - INFO - Waiting for all ready from discovery service. | E5: 2023-02-28 17:48:26,868 - PubAppln - INFO - Waiting for all ready from discovery service.
A6: 2023-02-28 17:48:31,472 - PubAppln - INFO - All sub and pub apps registered and ready. | C6: 2023-02-28 17:48:30,558 - PubAppln - INFO - All sub and pub apps registered and ready. | E6: 2023-02-28 17:48:32,275 - PubAppln - INFO - All sub and pub apps registered and ready.
A7: 2023-02-28 17:48:33,774 - PubAppln - INFO - Disseminating info on our topics. | C7: 2023-02-28 17:48:32,621 - PubAppln - INFO - Disseminating info on our topics. | E7: 2023-02-28 17:48:34,721 - PubAppln - INFO - Disseminating info on our topics.
A8: 2023-02-28 17:48:33,775 - PubAppln - INFO - Dissemination finished. Exiting. | C8: 2023-02-28 17:48:32,621 - PubAppln - INFO - Dissemination finished. Exiting. | E8: 2023-02-28 17:48:34,722 - PubAppln - INFO - Dissemination finished. Exiting.
B9: =34722-27862 -> 6860 | D9: =34722-28860 -> 5862 | F9: =34722-29847 -> 4875
A10: 2023-02-28 17:48:27,862 - SubAppln - INFO - Subscriber app configured. | C10: 2023-02-28 17:48:28,860 - SubAppln - INFO - Subscriber app configured. | E10: 2023-02-28 17:48:29,847 - SubAppln - INFO - Subscriber app configured.
A11: 2023-02-28 17:48:27,863 - SubAppln - INFO - Registering app with discovery service. | C11: 2023-02-28 17:48:28,860 - SubAppln - INFO - Registering app with discovery service. | E11: 2023-02-28 17:48:29,847 - SubAppln - INFO - Registering app with discovery service.
A12: 2023-02-28 17:48:27,879 - SubAppln - INFO - Subscriber app registered. | C12: 2023-02-28 17:48:28,894 - SubAppln - INFO - Subscriber app registered. | E12: 2023-02-28 17:48:29,877 - SubAppln - INFO - Subscriber app registered.
A13: 2023-02-28 17:48:27,879 - SubAppln - INFO - Waiting for all ready from discovery service. | C13: 2023-02-28 17:48:28,894 - SubAppln - INFO - Waiting for all ready from discovery service. | E13: 2023-02-28 17:48:29,877 - SubAppln - INFO - Waiting for all ready from discovery service.
A14: 2023-02-28 17:48:31,653 - SubAppln - INFO - All sub and pub apps registered and ready. | C14: 2023-02-28 17:48:30,811 - SubAppln - INFO - All sub and pub apps registered and ready. | E14: 2023-02-28 17:48:29,877 - SubAppln - INFO - All sub and pub apps registered and ready.
A15: 2023-02-28 17:48:31,991 - SubAppln - INFO - Locating all publishers for our topics. | C15: 2023-02-28 17:48:31,275 - SubAppln - INFO - Locating all publishers for our topics. | E15: 2023-02-28 17:48:30,120 - SubAppln - INFO - Locating all publishers for our topics.
A16: 2023-02-28 17:48:31,998 - SubAppln - INFO - Subscribing to relevant publishers. | C16: 2023-02-28 17:48:31,346 - SubAppln - INFO - Subscribing to relevant publishers. | E16: 2023-02-28 17:48:30,156 - SubAppln - INFO - Subscribing to relevant publishers.
A17: 2023-02-28 17:48:31,998 - SubAppln - INFO - Subscribed to publisher: tcp://10.0.0.5:5566 | C17: 2023-02-28 17:48:31,346 - SubAppln - INFO - Subscribed to publisher: tcp://10.0.0.5:5566 | E17: 2023-02-28 17:48:30,157 - SubAppln - INFO - Subscribed to publisher: tcp://10.0.0.5:5566
A18: 2023-02-28 17:48:31,998 - SubAppln - INFO - Subscribed to publisher: tcp://10.0.0.6:5566 | C18: 2023-02-28 17:48:31,346 - SubAppln - INFO - Subscribed to publisher: tcp://10.0.0.6:5566 | E18: 2023-02-28 17:48:30,157 - SubAppln - INFO - Subscribed to publisher: tcp://10.0.0.6:5566
A19: 2023-02-28 17:48:31,998 - SubAppln - INFO - Subscribed to publisher: tcp://10.0.0.7:5566 | C19: 2023-02-28 17:48:31,346 - SubAppln - INFO - Subscribed to publisher: tcp://10.0.0.7:5566 | E19: 2023-02-28 17:48:30,157 - SubAppln - INFO - Subscribed to publisher: tcp://10.0.0.7:5566
A20: 2023-02-28 17:48:32,621 - SubAppln - INFO - Message from publisher: airquality:smog | C20: 2023-02-28 17:48:32,621 - SubAppln - INFO - Message from publisher: airquality:smog | E20: 2023-02-28 17:48:32,621 - SubAppln - INFO - Message from publisher: airquality:smog
A21: 2023-02-28 17:48:32,621 - SubAppln - INFO - Message from publisher: location:America | C21: 2023-02-28 17:48:32,621 - SubAppln - INFO - Message from publisher: pressure:1000 | E21: 2023-02-28 17:48:32,621 - SubAppln - INFO - Message from publisher: pressure:1000
... A64: 2023-02-28 17:48:34,722 - SubAppln - INFO - Message from publisher: humidity:14.078545647240338 | C64: 2023-02-28 17:48:32,622 - SubAppln - INFO - Message from publisher: weather:rainy | E64: 2023-02-28 17:48:33,775 - SubAppln - INFO - Message from publisher: sound:49
C65: 2023-02-28 17:48:33,775 - SubAppln - INFO - Message from publisher: location:Asia | E65: 2023-02-28 17:48:33,775 - SubAppln - INFO - Message from publisher: airquality:smog
C66: 2023-02-28 17:48:33,775 - SubAppln - INFO - Message from publisher: pressure:885 | E66: 2023-02-28 17:48:33,775 - SubAppln - INFO - Message from publisher: weather:foggy
C67: 2023-02-28 17:48:33,775 - SubAppln - INFO - Message from publisher: temperature:-16 | E67: 2023-02-28 17:48:33,775 - SubAppln - INFO - Message from publisher: humidity:65.5059263798436
C68: 2023-02-28 17:48:33,775 - SubAppln - INFO - Message from publisher: sound:55 | E68: 2023-02-28 17:48:33,775 - SubAppln - INFO - Message from publisher: altitude:9014
C69: 2023-02-28 17:48:33,775 - SubAppln - INFO - Message from publisher: airquality:poor | E69: 2023-02-28 17:48:33,775 - SubAppln - INFO - Message from publisher: pressure:962
C70: 2023-02-28 17:48:33,775 - SubAppln - INFO - Message from publisher: weather:foggy | E70: 2023-02-28 17:48:33,775 - SubAppln - INFO - Message from publisher: temperature:-70
C71: 2023-02-28 17:48:33,775 - SubAppln - INFO - Message from publisher: humidity:41.9085300143908 | E71: 2023-02-28 17:48:33,775 - SubAppln - INFO - Message from publisher: sound:46
C72: 2023-02-28 17:48:33,775 - SubAppln - INFO - Message from publisher: altitude:37919 | E72: 2023-02-28 17:48:33,775 - SubAppln - INFO - Message from publisher: airquality:poor
C73: 2023-02-28 17:48:33,775 - SubAppln - INFO - Message from publisher: light:1100 | E73: 2023-02-28 17:48:33,775 - SubAppln - INFO - Message from publisher: weather:cloudy
C74: 2023-02-28 17:48:33,775 - SubAppln - INFO - Message from publisher: location:Australia | E74: 2023-02-28 17:48:33,775 - SubAppln - INFO - Message from publisher: humidity:71.56406403433459
C75: 2023-02-28 17:48:33,775 - SubAppln - INFO - Message from publisher: pressure:960 | E75: 2023-02-28 17:48:33,775 - SubAppln - INFO - Message from publisher: altitude:37545
C76: 2023-02-28 17:48:33,775 - SubAppln - INFO - Message from publisher: temperature:11 | E76: 2023-02-28 17:48:33,775 - SubAppln - INFO - Message from publisher: pressure:1027
... C94: 2023-02-28 17:48:33,776 - SubAppln - INFO - Message from publisher: temperature:-7 | E94: 2023-02-28 17:48:34,722 - SubAppln - INFO - Message from publisher: humidity:14.078545647240338
C95: 2023-02-28 17:48:33,776 - SubAppln - INFO - Message from publisher: sound:84
C96: 2023-02-28 17:48:33,776 - SubAppln - INFO - Message from publisher: airquality:good
C97: 2023-02-28 17:48:33,776 - SubAppln - INFO - Message from publisher: weather:sunny
C98: 2023-02-28 17:48:33,776 - SubAppln - INFO - Message from publisher: humidity:40.15145097595684
C99: 2023-02-28 17:48:33,776 - SubAppln - INFO - Message from publisher: altitude:38901
C100: 2023-02-28 17:48:33,776 - SubAppln - INFO - Message from publisher: light:450
...

Sheet Broker Central
A2: 2023-02-28 15:11:30,473 - PubAppln - INFO - Publisher app configured. | C2: 2023-02-28 15:11:31,491 - PubAppln - INFO - Publisher app configured. | E2: 2023-02-28 15:11:32,491 - PubAppln - INFO - Publisher app configured.
A3: 2023-02-28 15:11:30,473 - PubAppln - INFO - Registering app with discovery service. | C3: 2023-02-28 15:11:31,491 - PubAppln - INFO - Registering app with discovery service. | E3: 2023-02-28 15:11:32,491 - PubAppln - INFO - Registering app with discovery service.
A4: 2023-02-28 15:11:30,475 - PubAppln - INFO - Publisher app registered. | C4: 2023-02-28 15:11:31,493 - PubAppln - INFO - Publisher app registered. | E4: 2023-02-28 15:11:32,493 - PubAppln - INFO - Publisher app registered.
A5: 2023-02-28 15:11:30,475 - PubAppln - INFO - Waiting for all ready from discovery service. | C5: 2023-02-28 15:11:31,493 - PubAppln - INFO - Waiting for all ready from discovery service. | E5: 2023-02-28 15:11:32,493 - PubAppln - INFO - Waiting for all ready from discovery service.
A6: 2023-02-28 15:11:36,484 - PubAppln - INFO - All sub and pub apps registered and ready. | C6: 2023-02-28 15:11:35,499 - PubAppln - INFO - All sub and pub apps registered and ready. | E6: 2023-02-28 15:11:35,497 - PubAppln - INFO - All sub and pub apps registered and ready.
A7: 2023-02-28 15:11:37,486 - PubAppln - INFO - Disseminating info on our topics. | C7: 2023-02-28 15:11:36,500 - PubAppln - INFO - Disseminating info on our topics. | E7: 2023-02-28 15:11:36,498 - PubAppln - INFO - Disseminating info on our topics.
A8: 2023-02-28 15:11:37,486 - PubAppln - INFO - Dissemination finished. Exiting. | C8: 2023-02-28 15:11:36,500 - PubAppln - INFO - Dissemination finished. Exiting. | E8: 2023-02-28 15:11:36,499 - PubAppln - INFO - Dissemination finished. Exiting.
B9: =37488-33509 -> 3979 | D9: =37488-34497 -> 2991 | F9: =37488-35491 -> 1997
A10: 2023-02-28 15:11:33,509 - SubAppln - INFO - Subscriber app configured. | C10: 2023-02-28 15:11:34,497 - SubAppln - INFO - Subscriber app configured. | E10: 2023-02-28 15:11:35,491 - SubAppln - INFO - Subscriber app configured.
A11: 2023-02-28 15:11:33,509 - SubAppln - INFO - Registering app with discovery service. | C11: 2023-02-28 15:11:34,497 - SubAppln - INFO - Registering app with discovery service. | E11: 2023-02-28 15:11:35,491 - SubAppln - INFO - Registering app with discovery service.
A12: 2023-02-28 15:11:33,513 - SubAppln - INFO - Subscriber app registered. | C12: 2023-02-28 15:11:34,499 - SubAppln - INFO - Subscriber app registered. | E12: 2023-02-28 15:11:35,494 - SubAppln - INFO - Subscriber app registered.
A13: 2023-02-28 15:11:33,513 - SubAppln - INFO - Waiting for all ready from discovery service. | C13: 2023-02-28 15:11:34,499 - SubAppln - INFO - Waiting for all ready from discovery service. | E13: 2023-02-28 15:11:35,494 - SubAppln - INFO - Waiting for all ready from discovery service.
A14: 2023-02-28 15:11:35,517 - SubAppln - INFO - All sub and pub apps registered and ready. | C14: 2023-02-28 15:11:35,500 - SubAppln - INFO - All sub and pub apps registered and ready. | E14: 2023-02-28 15:11:35,494 - SubAppln - INFO - All sub and pub apps registered and ready.
A15: 2023-02-28 15:11:35,517 - SubAppln - INFO - Locating all publishers for our topics. | C15: 2023-02-28 15:11:35,500 - SubAppln - INFO - Locating all publishers for our topics. | E15: 2023-02-28 15:11:35,494 - SubAppln - INFO - Locating all publishers for our topics.
A16: 2023-02-28 15:11:35,517 - SubAppln - INFO - Subscribing to relevant publishers. | C16: 2023-02-28 15:11:35,501 - SubAppln - INFO - Subscribing to relevant publishers. | E16: 2023-02-28 15:11:35,495 - SubAppln - INFO - Subscribing to relevant publishers.
A17: 2023-02-28 15:11:35,517 - SubAppln - INFO - Subscribed to publisher: tcp://10.0.0.2:5588 | C17: 2023-02-28 15:11:35,501 - SubAppln - INFO - Subscribed to publisher: tcp://10.0.0.2:5588 | E17: 2023-02-28 15:11:35,495 - SubAppln - INFO - Subscribed to publisher: tcp://10.0.0.2:5588
A18: 2023-02-28 15:11:36,499 - SubAppln - INFO - Message from publisher: humidity:52.571284934569945 | C18: 2023-02-28 15:11:36,499 - SubAppln - INFO - Message from publisher: humidity:52.571284934569945 | E18: 2023-02-28 15:11:37,487 - SubAppln - INFO - Message from publisher: pressure:962
A19: 2023-02-28 15:11:36,500 - SubAppln - INFO - Message from publisher: sound:58 | C19: 2023-02-28 15:11:36,499 - SubAppln - INFO - Message from publisher: sound:58 | E19: 2023-02-28 15:11:37,487 - SubAppln - INFO - Message from publisher: pressure:946
A20: 2023-02-28 15:11:36,500 - SubAppln - INFO - Message from publisher: temperature:-2 | C20: 2023-02-28 15:11:36,499 - SubAppln - INFO - Message from publisher: weather:cloudy | E20: 2023-02-28 15:11:37,487 - SubAppln - INFO - Message from publisher: pressure:981
A21: 2023-02-28 15:11:36,500 - SubAppln - INFO - Message from publisher: humidity:15.793822963017885 | C21: 2023-02-28 15:11:36,500 - SubAppln - INFO - Message from publisher: temperature:-2 | E21: 2023-02-28 15:11:37,487 - SubAppln - INFO - Message from publisher: pressure:999
A22: 2023-02-28 15:11:36,500 - SubAppln - INFO - Message from publisher: sound:30 | C22: 2023-02-28 15:11:36,500 - SubAppln - INFO - Message from publisher: humidity:15.793822963017885 | E22: 2023-02-28 15:11:37,488 - SubAppln - INFO - Message from publisher: pressure:892
A23: 2023-02-28 15:11:36,500 - SubAppln - INFO - Message from publisher: temperature:-90 | C23: 2023-02-28 15:11:36,500 - SubAppln - INFO - Message from publisher: sound:30
A24: 2023-02-28 15:11:36,500 - SubAppln - INFO - Message from publisher: humidity:60.65591799060585 | C24: 2023-02-28 15:11:36,500 - SubAppln - INFO - Message from publisher: weather:icy
A25: 2023-02-28 15:11:36,500 - SubAppln - INFO - Message from publisher: sound:67 | C25: 2023-02-28 15:11:36,500 - SubAppln - INFO - Message from publisher: temperature:-90
A26: 2023-02-28 15:11:36,500 - SubAppln - INFO - Message from publisher: temperature:-10 | C26: 2023-02-28 15:11:36,500 - SubAppln - INFO - Message from publisher: humidity:60.65591799060585
A27: 2023-02-28 15:11:36,500 - SubAppln - INFO - Message from publisher: humidity:26.472035026701306 | C27: 2023-02-28 15:11:36,500 - SubAppln - INFO - Message from publisher: sound:67
A28: 2023-02-28 15:11:36,500 - SubAppln - INFO - Message from publisher: sound:86 | C28: 2023-02-28 15:11:36,500 - SubAppln - INFO - Message from publisher: weather:sunny
A29: 2023-02-28 15:11:36,500 - SubAppln - INFO - Message from publisher: temperature:-18 | C29: 2023-02-28 15:11:36,500 - SubAppln - INFO - Message from publisher: temperature:-10
A30: 2023-02-28 15:11:36,500 - SubAppln - INFO - Message from publisher: humidity:87.33280857352192 | C30: 2023-02-28 15:11:36,500 - SubAppln - INFO - Message from publisher: humidity:26.472035026701306
A31: 2023-02-28 15:11:36,500 - SubAppln - INFO - Message from publisher: sound:95 | C31: 2023-02-28 15:11:36,500 - SubAppln - INFO - Message from publisher: sound:86
A32: 2023-02-28 15:11:36,500 - SubAppln - INFO - Message from publisher: temperature:55 | C32: 2023-02-28 15:11:36,500 - SubAppln - INFO - Message from publisher: weather:foggy
A33: 2023-02-28 15:11:37,486 - SubAppln - INFO - Message from publisher: humidity:23.277099357642562 | C33: 2023-02-28 15:11:36,500 - SubAppln - INFO - Message from publisher: temperature:-18
A34: 2023-02-28 15:11:37,486 - SubAppln - INFO - Message from publisher: temperature:70 | C34: 2023-02-28 15:11:36,500 - SubAppln - INFO - Message from publisher: humidity:87.33280857352192
... A62: 2023-02-28 15:11:37,488 - SubAppln - INFO - Message from publisher: altitude:3153 | C62: 2023-02-28 15:11:37,488 - SubAppln - INFO - Message from publisher: weather:sunny
C63: 2023-02-28 15:11:37,488 - SubAppln - INFO - Message from publisher: altitude:20385
C64: 2023-02-28 15:11:37,488 - SubAppln - INFO - Message from publisher: humidity:16.775098175201556
C65: 2023-02-28 15:11:37,488 - SubAppln - INFO - Message from publisher: temperature:-60
C66: 2023-02-28 15:11:37,488 - SubAppln - INFO - Message from publisher: sound:59
C67: 2023-02-28 15:11:37,488 - SubAppln - INFO - Message from publisher: pressure:999
C68: 2023-02-28 15:11:37,488 - SubAppln - INFO - Message from publisher: location:Africa
...

Sheet Broker Distributed
A2: 2023-02-28 17:47:40,828 - PubAppln - INFO - Publisher app configured. | C2: 2023-02-28 17:47:41,820 - PubAppln - INFO - Publisher app configured. | E2: 2023-02-28 17:47:42,827 - PubAppln - INFO - Publisher app configured.
A3: 2023-02-28 17:47:40,828 - PubAppln - INFO - Registering app with discovery service. | C3: 2023-02-28 17:47:41,821 - PubAppln - INFO - Registering app with discovery service. | E3: 2023-02-28 17:47:42,827 - PubAppln - INFO - Registering app with discovery service.
A4: 2023-02-28 17:47:40,838 - PubAppln - INFO - Publisher app registered. | C4: 2023-02-28 17:47:41,835 - PubAppln - INFO - Publisher app registered. | E4: 2023-02-28 17:47:42,861 - PubAppln - INFO - Publisher app registered.
A5: 2023-02-28 17:47:40,838 - PubAppln - INFO - Waiting for all ready from discovery service. | C5: 2023-02-28 17:47:41,835 - PubAppln - INFO - Waiting for all ready from discovery service. | E5: 2023-02-28 17:47:42,861 - PubAppln - INFO - Waiting for all ready from discovery service.
A6: 2023-02-28 17:47:48,169 - PubAppln - INFO - All sub and pub apps registered and ready. | C6: 2023-02-28 17:47:46,068 - PubAppln - INFO - All sub and pub apps registered and ready. | E6: 2023-02-28 17:47:48,408 - PubAppln - INFO - All sub and pub apps registered and ready.
A7: 2023-02-28 17:47:50,611 - PubAppln - INFO - Disseminating info on our topics. | C7: 2023-02-28 17:47:48,234 - PubAppln - INFO - Disseminating info on our topics. | E7: 2023-02-28 17:47:50,707 - PubAppln - INFO - Disseminating info on our topics.
A8: 2023-02-28 17:47:50,611 - PubAppln - INFO - Dissemination finished. Exiting. | C8: 2023-02-28 17:47:48,234 - PubAppln - INFO - Dissemination finished. Exiting. | E8: 2023-02-28 17:47:50,707 - PubAppln - INFO - Dissemination finished. Exiting.
B9: =50708-43837 -> 6871 | D9: =50709-44843 -> 5866 | F9: =50708-45838 -> 4870
A10: 2023-02-28 17:47:43,837 - SubAppln - INFO - Subscriber app configured. | C10: 2023-02-28 17:47:44,843 - SubAppln - INFO - Subscriber app configured. | E10: 2023-02-28 17:47:45,838 - SubAppln - INFO - Subscriber app configured.
A11: 2023-02-28 17:47:43,837 - SubAppln - INFO - Registering app with discovery service. | C11: 2023-02-28 17:47:44,843 - SubAppln - INFO - Registering app with discovery service. | E11: 2023-02-28 17:47:45,838 - SubAppln - INFO - Registering app with discovery service.
A12: 2023-02-28 17:47:43,849 - SubAppln - INFO - Subscriber app registered. | C12: 2023-02-28 17:47:44,864 - SubAppln - INFO - Subscriber app registered. | E12: 2023-02-28 17:47:45,867 - SubAppln - INFO - Subscriber app registered.
A13: 2023-02-28 17:47:43,849 - SubAppln - INFO - Waiting for all ready from discovery service. | C13: 2023-02-28 17:47:44,864 - SubAppln - INFO - Waiting for all ready from discovery service. | E13: 2023-02-28 17:47:45,867 - SubAppln - INFO - Waiting for all ready from discovery service.
A14: 2023-02-28 17:47:48,269 - SubAppln - INFO - All sub and pub apps registered and ready. | C14: 2023-02-28 17:47:47,258 - SubAppln - INFO - All sub and pub apps registered and ready. | E14: 2023-02-28 17:47:45,867 - SubAppln - INFO - All sub and pub apps registered and ready.
A15: 2023-02-28 17:47:48,690 - SubAppln - INFO - Locating all publishers for our topics. | C15: 2023-02-28 17:47:48,057 - SubAppln - INFO - Locating all publishers for our topics. | E15: 2023-02-28 17:47:46,541 - SubAppln - INFO - Locating all publishers for our topics.
A16: 2023-02-28 17:47:48,691 - SubAppln - INFO - Subscribing to relevant publishers. | C16: 2023-02-28 17:47:48,057 - SubAppln - INFO - Subscribing to relevant publishers. | E16: 2023-02-28 17:47:46,541 - SubAppln - INFO - Subscribing to relevant publishers.
A17: 2023-02-28 17:47:48,691 - SubAppln - INFO - Subscribed to publisher: tcp://10.0.0.5:5588 | C17: 2023-02-28 17:47:48,058 - SubAppln - INFO - Subscribed to publisher: tcp://10.0.0.5:5588 | E17: 2023-02-28 17:47:46,541 - SubAppln - INFO - Subscribed to publisher: tcp://10.0.0.5:5588
A18: 2023-02-28 17:47:50,612 - SubAppln - INFO - Message from publisher: pressure:962 | C18: 2023-02-28 17:47:50,612 - SubAppln - INFO - Message from publisher: pressure:962 | E18: 2023-02-28 17:47:50,612 - SubAppln - INFO - Message from publisher: pressure:962
A19: 2023-02-28 17:47:50,612 - SubAppln - INFO - Message from publisher: pressure:969 | C19: 2023-02-28 17:47:50,612 - SubAppln - INFO - Message from publisher: pressure:969 | E19: 2023-02-28 17:47:50,612 - SubAppln - INFO - Message from publisher: humidity:38.888908200866965
A20: 2023-02-28 17:47:50,612 - SubAppln - INFO - Message from publisher: pressure:882 | C20: 2023-02-28 17:47:50,612 - SubAppln - INFO - Message from publisher: pressure:882 | E20: 2023-02-28 17:47:50,612 - SubAppln - INFO - Message from publisher: location:Africa
A21: 2023-02-28 17:47:50,612 - SubAppln - INFO - Message from publisher: pressure:1032 | C21: 2023-02-28 17:47:50,612 - SubAppln - INFO - Message from publisher: pressure:1032 | E21: 2023-02-28 17:47:50,612 - SubAppln - INFO - Message from publisher: pressure:969
... A42: 2023-02-28 17:47:50,708 - SubAppln - INFO - Message from publisher: temperature:-18 | C42: 2023-02-28 17:47:50,709 - SubAppln - INFO - Message from publisher: temperature:-6 | E42: 2023-02-28 17:47:50,707 - SubAppln - INFO - Message from publisher: pressure:893
C43: 2023-02-28 17:47:50,709 - SubAppln - INFO - Message from publisher: weather:icy | E43: 2023-02-28 17:47:50,708 - SubAppln - INFO - Message from publisher: sound:56
C44: 2023-02-28 17:47:50,709 - SubAppln - INFO - Message from publisher: pressure:895 | E44: 2023-02-28 17:47:50,708 - SubAppln - INFO - Message from publisher: light:1100
C45: 2023-02-28 17:47:50,709 - SubAppln - INFO - Message from publisher: sound:89 | E45: 2023-02-28 17:47:50,708 - SubAppln - INFO - Message from publisher: location:America
C46: 2023-02-28 17:47:50,709 - SubAppln - INFO - Message from publisher: light:1600 | E46: 2023-02-28 17:47:50,708 - SubAppln - INFO - Message from publisher: humidity:89.99375903065796
C47: 2023-02-28 17:47:50,709 - SubAppln - INFO - Message from publisher: temperature:-18 | E47: 2023-02-28 17:47:50,708 - SubAppln - INFO - Message from publisher: airquality:good
E48: 2023-02-28 17:47:50,708 - SubAppln - INFO - Message from publisher: temperature:-36
E49: 2023-02-28 17:47:50,708 - SubAppln - INFO - Message from publisher: weather:foggy
E50: 2023-02-28 17:47:50,708 - SubAppln - INFO - Message from publisher: pressure:997
E51: 2023-02-28 17:47:50,708 - SubAppln - INFO - Message from publisher: sound:31
E52: 2023-02-28 17:47:50,708 - SubAppln - INFO - Message from publisher: light:1600
E53: 2023-02-28 17:47:50,708 - SubAppln - INFO - Message from publisher: location:Asia
E54: 2023-02-28 17:47:50,708 - SubAppln - INFO - Message from publisher: humidity:64.69829498238029
E55: 2023-02-28 17:47:50,708 - SubAppln - INFO - Message from publisher: airquality:poor
E56: 2023-02-28 17:47:50,708 - SubAppln - INFO - Message from publisher: temperature:70
E57: 2023-02-28 17:47:50,708 - SubAppln - INFO - Message from publisher: weather:foggy
E58: 2023-02-28 17:47:50,708 - SubAppln - INFO - Message from publisher: pressure:905
E59: 2023-02-28 17:47:50,708 - SubAppln - INFO - Message from publisher: sound:68
... E72: 2023-02-28 17:47:50,708 - SubAppln - INFO - Message from publisher: temperature:-18
